INFO:werkzeug: * Running on http://0.0.0.0:5000/ (Press CTRL+C to quit)
INFO:werkzeug:127.0.0.1 - - [25/Apr/2020 17:10:53] "[37mGET / HTTP/1.1[0m" 200 -
INFO:werkzeug:127.0.0.1 - - [25/Apr/2020 17:11:09] "[37mGET /search?q=eggs&minTime=0&maxTime=9999 HTTP/1.1[0m" 200 -
INFO:werkzeug:127.0.0.1 - - [25/Apr/2020 17:11:09] "[37mGET /data/allrecipes/images/userphotos/250x250/870530.jpg HTTP/1.1[0m" 200 -
INFO:werkzeug:127.0.0.1 - - [25/Apr/2020 17:11:09] "[37mGET /data/allrecipes/images/userphotos/560x315/4254003.jpg HTTP/1.1[0m" 200 -
INFO:werkzeug:127.0.0.1 - - [25/Apr/2020 17:11:09] "[37mGET /data/allrecipes/images/userphotos/560x315/1132117.jpg HTTP/1.1[0m" 200 -
INFO:werkzeug:127.0.0.1 - - [25/Apr/2020 17:11:09] "[37mGET /data/allrecipes/images/userphotos/560x315/4253976.jpg HTTP/1.1[0m" 200 -
INFO:werkzeug:127.0.0.1 - - [25/Apr/2020 17:11:09] "[37mGET /data/allrecipes/images/userphotos/560x315/4473754.jpg HTTP/1.1[0m" 200 -
INFO:werkzeug:127.0.0.1 - - [25/Apr/2020 17:11:09] "[37mGET /data/allrecipes/images/userphotos/250x250/396821.jpg HTTP/1.1[0m" 200 -
INFO:werkzeug:127.0.0.1 - - [25/Apr/2020 17:11:09] "[37mGET /data/allrecipes/images/userphotos/250x250/826931.jpg HTTP/1.1[0m" 200 -
INFO:werkzeug:127.0.0.1 - - [25/Apr/2020 17:11:09] "[37mGET /data/allrecipes/images/userphotos/250x250/992698.jpg HTTP/1.1[0m" 200 -
INFO:werkzeug:127.0.0.1 - - [25/Apr/2020 17:11:09] "[37mGET /data/allrecipes/images/userphotos/250x250/855842.jpg HTTP/1.1[0m" 200 -
INFO:werkzeug:127.0.0.1 - - [25/Apr/2020 17:11:09] "[37mGET /data/allrecipes/images/userphotos/560x315/4465319.jpg HTTP/1.1[0m" 200 -
INFO:werkzeug:127.0.0.1 - - [25/Apr/2020 17:11:09] "[37mGET /data/allrecipes/images/userphotos/250x250/985099.jpg HTTP/1.1[0m" 200 -
INFO:werkzeug: * Running on http://0.0.0.0:5000/ (Press CTRL+C to quit)
INFO:werkzeug: * Running on http://0.0.0.0:5000/ (Press CTRL+C to quit)
ERROR:server:Exception on /search [GET]
Traceback (most recent call last):
  File "/Users/hoeunsim2/dev/recipe-recommender/venv/lib/python3.7/site-packages/flask/app.py", line 2447, in wsgi_app
    response = self.full_dispatch_request()
  File "/Users/hoeunsim2/dev/recipe-recommender/venv/lib/python3.7/site-packages/flask/app.py", line 1952, in full_dispatch_request
    rv = self.handle_user_exception(e)
  File "/Users/hoeunsim2/dev/recipe-recommender/venv/lib/python3.7/site-packages/flask/app.py", line 1821, in handle_user_exception
    reraise(exc_type, exc_value, tb)
  File "/Users/hoeunsim2/dev/recipe-recommender/venv/lib/python3.7/site-packages/flask/_compat.py", line 39, in reraise
    raise value
  File "/Users/hoeunsim2/dev/recipe-recommender/venv/lib/python3.7/site-packages/flask/app.py", line 1950, in full_dispatch_request
    rv = self.dispatch_request()
  File "/Users/hoeunsim2/dev/recipe-recommender/venv/lib/python3.7/site-packages/flask/app.py", line 1936, in dispatch_request
    return self.view_functions[rule.endpoint](**req.view_args)
  File "server.py", line 46, in search
    abort(422, "Missing query")     # 422 unprocessable entity
NameError: name 'abort' is not defined
INFO:werkzeug:127.0.0.1 - - [26/Apr/2020 21:03:46] "[35m[1mGET /search HTTP/1.1[0m" 500 -
ERROR:server:Exception on / [GET]
Traceback (most recent call last):
  File "/Users/hoeunsim2/dev/recipe-recommender/venv/lib/python3.7/site-packages/flask/app.py", line 2447, in wsgi_app
    response = self.full_dispatch_request()
  File "/Users/hoeunsim2/dev/recipe-recommender/venv/lib/python3.7/site-packages/flask/app.py", line 1952, in full_dispatch_request
    rv = self.handle_user_exception(e)
  File "/Users/hoeunsim2/dev/recipe-recommender/venv/lib/python3.7/site-packages/flask/app.py", line 1821, in handle_user_exception
    reraise(exc_type, exc_value, tb)
  File "/Users/hoeunsim2/dev/recipe-recommender/venv/lib/python3.7/site-packages/flask/_compat.py", line 39, in reraise
    raise value
  File "/Users/hoeunsim2/dev/recipe-recommender/venv/lib/python3.7/site-packages/flask/app.py", line 1950, in full_dispatch_request
    rv = self.dispatch_request()
  File "/Users/hoeunsim2/dev/recipe-recommender/venv/lib/python3.7/site-packages/flask/app.py", line 1936, in dispatch_request
    return self.view_functions[rule.endpoint](**req.view_args)
  File "server.py", line 16, in index
    with open('../static/index.html', 'r', encoding='utf-8') as file:
FileNotFoundError: [Errno 2] No such file or directory: '../static/index.html'
INFO:werkzeug:127.0.0.1 - - [26/Apr/2020 21:04:19] "[35m[1mGET / HTTP/1.1[0m" 500 -
INFO:werkzeug:127.0.0.1 - - [26/Apr/2020 21:04:20] "[33mGET /favicon.ico HTTP/1.1[0m" 404 -
ERROR:server:Exception on / [GET]
Traceback (most recent call last):
  File "/Users/hoeunsim2/dev/recipe-recommender/venv/lib/python3.7/site-packages/flask/app.py", line 2447, in wsgi_app
    response = self.full_dispatch_request()
  File "/Users/hoeunsim2/dev/recipe-recommender/venv/lib/python3.7/site-packages/flask/app.py", line 1952, in full_dispatch_request
    rv = self.handle_user_exception(e)
  File "/Users/hoeunsim2/dev/recipe-recommender/venv/lib/python3.7/site-packages/flask/app.py", line 1821, in handle_user_exception
    reraise(exc_type, exc_value, tb)
  File "/Users/hoeunsim2/dev/recipe-recommender/venv/lib/python3.7/site-packages/flask/_compat.py", line 39, in reraise
    raise value
  File "/Users/hoeunsim2/dev/recipe-recommender/venv/lib/python3.7/site-packages/flask/app.py", line 1950, in full_dispatch_request
    rv = self.dispatch_request()
  File "/Users/hoeunsim2/dev/recipe-recommender/venv/lib/python3.7/site-packages/flask/app.py", line 1936, in dispatch_request
    return self.view_functions[rule.endpoint](**req.view_args)
  File "server.py", line 16, in index
    with open('../static/index.html', 'r', encoding='utf-8') as file:
FileNotFoundError: [Errno 2] No such file or directory: '../static/index.html'
INFO:werkzeug:127.0.0.1 - - [26/Apr/2020 21:04:28] "[35m[1mGET / HTTP/1.1[0m" 500 -
INFO:werkzeug: * Running on http://0.0.0.0:5000/ (Press CTRL+C to quit)
ERROR:server:Exception on / [GET]
Traceback (most recent call last):
  File "/Users/hoeunsim2/dev/recipe-recommender/venv/lib/python3.7/site-packages/flask/app.py", line 2447, in wsgi_app
    response = self.full_dispatch_request()
  File "/Users/hoeunsim2/dev/recipe-recommender/venv/lib/python3.7/site-packages/flask/app.py", line 1952, in full_dispatch_request
    rv = self.handle_user_exception(e)
  File "/Users/hoeunsim2/dev/recipe-recommender/venv/lib/python3.7/site-packages/flask/app.py", line 1821, in handle_user_exception
    reraise(exc_type, exc_value, tb)
  File "/Users/hoeunsim2/dev/recipe-recommender/venv/lib/python3.7/site-packages/flask/_compat.py", line 39, in reraise
    raise value
  File "/Users/hoeunsim2/dev/recipe-recommender/venv/lib/python3.7/site-packages/flask/app.py", line 1950, in full_dispatch_request
    rv = self.dispatch_request()
  File "/Users/hoeunsim2/dev/recipe-recommender/venv/lib/python3.7/site-packages/flask/app.py", line 1936, in dispatch_request
    return self.view_functions[rule.endpoint](**req.view_args)
  File "server.py", line 16, in index
    with open('../static/index.html', 'r', encoding='utf-8') as file:
FileNotFoundError: [Errno 2] No such file or directory: '../static/index.html'
INFO:werkzeug:127.0.0.1 - - [26/Apr/2020 21:04:36] "[35m[1mGET / HTTP/1.1[0m" 500 -
INFO:werkzeug: * Running on http://0.0.0.0:5000/ (Press CTRL+C to quit)
ERROR:server:Exception on /search [GET]
Traceback (most recent call last):
  File "/Users/hoeunsim2/dev/recipe-recommender/venv/lib/python3.7/site-packages/flask/app.py", line 2447, in wsgi_app
    response = self.full_dispatch_request()
  File "/Users/hoeunsim2/dev/recipe-recommender/venv/lib/python3.7/site-packages/flask/app.py", line 1952, in full_dispatch_request
    rv = self.handle_user_exception(e)
  File "/Users/hoeunsim2/dev/recipe-recommender/venv/lib/python3.7/site-packages/flask/app.py", line 1821, in handle_user_exception
    reraise(exc_type, exc_value, tb)
  File "/Users/hoeunsim2/dev/recipe-recommender/venv/lib/python3.7/site-packages/flask/_compat.py", line 39, in reraise
    raise value
  File "/Users/hoeunsim2/dev/recipe-recommender/venv/lib/python3.7/site-packages/flask/app.py", line 1950, in full_dispatch_request
    rv = self.dispatch_request()
  File "/Users/hoeunsim2/dev/recipe-recommender/venv/lib/python3.7/site-packages/flask/app.py", line 1936, in dispatch_request
    return self.view_functions[rule.endpoint](**req.view_args)
  File "server.py", line 46, in search
    abort(422, "Missing query")     # 422 unprocessable entity
NameError: name 'abort' is not defined
INFO:werkzeug:127.0.0.1 - - [26/Apr/2020 21:05:42] "[35m[1mGET /search HTTP/1.1[0m" 500 -
ERROR:server:Exception on /search [GET]
Traceback (most recent call last):
  File "/Users/hoeunsim2/dev/recipe-recommender/venv/lib/python3.7/site-packages/flask/app.py", line 2447, in wsgi_app
    response = self.full_dispatch_request()
  File "/Users/hoeunsim2/dev/recipe-recommender/venv/lib/python3.7/site-packages/flask/app.py", line 1952, in full_dispatch_request
    rv = self.handle_user_exception(e)
  File "/Users/hoeunsim2/dev/recipe-recommender/venv/lib/python3.7/site-packages/flask/app.py", line 1821, in handle_user_exception
    reraise(exc_type, exc_value, tb)
  File "/Users/hoeunsim2/dev/recipe-recommender/venv/lib/python3.7/site-packages/flask/_compat.py", line 39, in reraise
    raise value
  File "/Users/hoeunsim2/dev/recipe-recommender/venv/lib/python3.7/site-packages/flask/app.py", line 1950, in full_dispatch_request
    rv = self.dispatch_request()
  File "/Users/hoeunsim2/dev/recipe-recommender/venv/lib/python3.7/site-packages/flask/app.py", line 1936, in dispatch_request
    return self.view_functions[rule.endpoint](**req.view_args)
  File "server.py", line 46, in search
    abort(422, "Missing query")     # 422 unprocessable entity
NameError: name 'abort' is not defined
INFO:werkzeug:127.0.0.1 - - [26/Apr/2020 21:05:42] "[35m[1mGET /search HTTP/1.1[0m" 500 -
ERROR:server:Exception on /search [GET]
Traceback (most recent call last):
  File "/Users/hoeunsim2/dev/recipe-recommender/venv/lib/python3.7/site-packages/flask/app.py", line 2447, in wsgi_app
    response = self.full_dispatch_request()
  File "/Users/hoeunsim2/dev/recipe-recommender/venv/lib/python3.7/site-packages/flask/app.py", line 1952, in full_dispatch_request
    rv = self.handle_user_exception(e)
  File "/Users/hoeunsim2/dev/recipe-recommender/venv/lib/python3.7/site-packages/flask/app.py", line 1821, in handle_user_exception
    reraise(exc_type, exc_value, tb)
  File "/Users/hoeunsim2/dev/recipe-recommender/venv/lib/python3.7/site-packages/flask/_compat.py", line 39, in reraise
    raise value
  File "/Users/hoeunsim2/dev/recipe-recommender/venv/lib/python3.7/site-packages/flask/app.py", line 1950, in full_dispatch_request
    rv = self.dispatch_request()
  File "/Users/hoeunsim2/dev/recipe-recommender/venv/lib/python3.7/site-packages/flask/app.py", line 1936, in dispatch_request
    return self.view_functions[rule.endpoint](**req.view_args)
  File "server.py", line 46, in search
    abort(422, "Missing query")     # 422 unprocessable entity
NameError: name 'abort' is not defined
INFO:werkzeug:127.0.0.1 - - [26/Apr/2020 21:05:45] "[35m[1mGET /search HTTP/1.1[0m" 500 -
ERROR:server:Exception on /search [GET]
Traceback (most recent call last):
  File "/Users/hoeunsim2/dev/recipe-recommender/venv/lib/python3.7/site-packages/flask/app.py", line 2447, in wsgi_app
    response = self.full_dispatch_request()
  File "/Users/hoeunsim2/dev/recipe-recommender/venv/lib/python3.7/site-packages/flask/app.py", line 1952, in full_dispatch_request
    rv = self.handle_user_exception(e)
  File "/Users/hoeunsim2/dev/recipe-recommender/venv/lib/python3.7/site-packages/flask/app.py", line 1821, in handle_user_exception
    reraise(exc_type, exc_value, tb)
  File "/Users/hoeunsim2/dev/recipe-recommender/venv/lib/python3.7/site-packages/flask/_compat.py", line 39, in reraise
    raise value
  File "/Users/hoeunsim2/dev/recipe-recommender/venv/lib/python3.7/site-packages/flask/app.py", line 1950, in full_dispatch_request
    rv = self.dispatch_request()
  File "/Users/hoeunsim2/dev/recipe-recommender/venv/lib/python3.7/site-packages/flask/app.py", line 1936, in dispatch_request
    return self.view_functions[rule.endpoint](**req.view_args)
  File "server.py", line 46, in search
    abort(422, "Missing query")     # 422 unprocessable entity
NameError: name 'abort' is not defined
INFO:werkzeug:127.0.0.1 - - [26/Apr/2020 21:05:47] "[35m[1mGET /search HTTP/1.1[0m" 500 -
